<?xml version="1.0"?>
<robot name="robot" xmlns:xacro="http://www.ros.org/wiki/xacro">
    
    <link name="base_footprint">
   		<visual>
			<geometry>
      				<box size="0.001 0.001 0.001"/>
     			</geometry>
			<origin rpy="0 0 0" xyz="0 0 0"/>
   		</visual>
		<xacro:default_inertial mass="0.0001"/>
 	</link>
  
	<gazebo reference="base_footprint">
		<material>Gazebo/Green</material>
		<turnGravityOff>false</turnGravityOff>
	</gazebo>

	<joint name="base_footprint_joint" type="fixed">
		<origin xyz="0 0 0" />
		<parent link="base_footprint" />
		<child link="base_link" />
	</joint>

	<link name="base_link">
   		<visual>
			<geometry>
      				<box size="0.556 0.597 0.1"/>
     			</geometry>
          
			<origin rpy="0 0 ${PI/2}" xyz="0 0 0.05"/>  
			<material name="white">　　　
				<color rgba="1 1 1 1"/>
			</material>
   		</visual>
		<collision>
			<geometry>
       				<box size="0.556 0.597 0.1"/>
			</geometry>
		</collision>
            <xacro:default_inertial mass="8.2"/>    
 	</link>


    <link name="wheel_1">
   		<visual>
     			<geometry>
       				 <cylinder length="${length_wheel}" radius="${radius_wheel}"/>
     			</geometry>
			<!-- <origin rpy="0 1.5 0" xyz="0.1 0.1 0"/> -->
			<origin rpy="0 0 0" xyz="0 0 0"/>
   			<material name="black">
				<color rgba="0 0 0 1"/>
			</material>
		</visual>
		<collision>
			<geometry>
       				 <cylinder length="${length_wheel}" radius="${radius_wheel}"/>
			</geometry>
		</collision>
		  <mu1>3</mu1>
		    <mu2>3</mu2>
		    <!-- <mu1>3</mu1>
		    <mu2>3</mu2> -->
		<xacro:default_inertial mass="0.05"/>  
 	</link>



 	<link name="wheel_2">
   		<visual>
     			<geometry>
       				 <cylinder length="${length_wheel}" radius="${radius_wheel}"/>
     			</geometry>
			<!-- <origin rpy="0 1.5 0" xyz="-0.1 0.1 0"/> -->
			<origin rpy="0 0 0" xyz="0 0 0"/>
   			<material name="black"/>
   		</visual>
		<collision>
			<geometry>
       				 <cylinder length="${length_wheel}" radius="${radius_wheel}"/>
			</geometry>
		</collision>
		   <mu1>3</mu1>
		    <mu2>3</mu2>
		    <!-- <mu1>3</mu1>
		    <mu2>3</mu2> -->
		<xacro:default_inertial mass="0.05"/>  

 	</link>
    
 	<link name="wheel_3">
   		<visual>
     			<geometry>
       				 <cylinder length="${length_wheel}" radius="${radius_wheel}"/>
     			</geometry>
			<!-- <origin rpy="0 1.5 0" xyz="0.1 -0.1 0"/> -->

			<origin rpy="0 0 0" xyz="0 0 0"/>
   			<material name="black"/>
   		</visual>
		<collision>
			<geometry>
       				 <cylinder length="${length_wheel}" radius="${radius_wheel}"/>
			</geometry>
		</collision>
		 <mu1>3</mu1>
		    <mu2>3</mu2>
		    <!-- <mu1>3</mu1>
		    <mu2>3</mu2> -->
		<xacro:default_inertial mass="0.05"/>    
 	</link>

 	<link name="wheel_4">
   		<visual>
     			<geometry>
       				 <cylinder length="${length_wheel}" radius="${radius_wheel}"/>
     			</geometry>
		<!--	<origin rpy="0 1.5 0" xyz="-0.1 -0.1 0"/> -->
			<origin rpy="0 0 0" xyz="0 0 0" />
   			<material name="black"/>
   		</visual>
		<collision>
			<geometry>
       				 <cylinder length="${length_wheel}" radius="${radius_wheel}"/>
			</geometry>
		</collision>
		   <mu1>3</mu1>
		    <mu2>3</mu2>
		    <!-- <mu1>3</mu1>
		    <mu2>3</mu2> -->
		<xacro:default_inertial mass="0.05"/>    

 	</link>



    <joint name="base_to_wheel1" type="continuous">
        <anchor xyz="0 0 0" />
        <limit effort="100" velocity="100" />
		<parent link="base_link"/>
        <child link="wheel_1"/>
        <origin rpy="${-PI/2} 0 0" xyz="0.3 0.24 0"/>
        <axis xyz="0 0 1" />
    </joint>

    <joint name="base_to_wheel2" type="continuous">
        <axis xyz="0 0 1" />
        <anchor xyz="0 0 0" />
        <limit effort="100" velocity="100" />
        <parent link="base_link"/>
        <child link="wheel_2"/>
        <origin rpy="${-PI/2} 0 0" xyz="-0.3 0.24 0"/>
    </joint>

    <joint name="base_to_wheel3" type="continuous">
        <anchor xyz="0 0 0" />
        <limit effort="100" velocity="100" />
		<parent link="base_link"/>
        <axis xyz="0 0 1" />
        <child link="wheel_3"/>
        <origin rpy="${-PI/2} 0 0" xyz="0.3 -0.24 0"/>
    </joint>

    <joint name="base_to_wheel4" type="continuous">
        <anchor xyz="0 0 0" />
        <limit effort="100" velocity="100" />
		<parent link="base_link"/>
        <axis xyz="0 0 1" />
        <child link="wheel_4"/>
        <origin rpy="${-PI/2} 0 0" xyz="-0.3 -0.24 0"/>
    </joint>




    <!-- gazebo插件设置相关 -->

    <gazebo reference="base_link">
        <material>Gazebo/Orange</material>
    </gazebo>

    <gazebo reference="wheel_1">
            <material>Gazebo/Red</material>
    </gazebo>

    <gazebo reference="wheel_2">
            <material>Gazebo/Black</material>
    </gazebo>

    <gazebo reference="wheel_3">
            <material>Gazebo/Red</material>
    </gazebo>

    <gazebo reference="wheel_4">
            <material>Gazebo/Black</material>
    </gazebo>

</robot>